Workbook
Name ActivityEnd: Parametri!$F$12:$F$18
Name ActivityStart: Parametri!$E$12:$E$18
Name AvailabilityGrid: Planner!$B$17:$H$40
Name AvailabilityStates: Calcoli!$R$17:$X$40
Name AvailableZoneCodes: ZoneCatalog[Code]
Name CalendarCodes: Calendari!$A$6:$A$25
Name CalendarKeys: Parametri!$D$12:$D$18
Name DataFolder: Parametri!$B$25
Name ExtendedStepMinutes: Parametri!$C$7
Name LocationLabels: Parametri!$B$12:$B$18
Name PlannerDate: Parametri!$C$5
Name ReserveAfterHours: Parametri!$J$6
Name ReserveBeforeHours: Parametri!$J$5
Name SchemaVersion: 2
Name StartLocalTime: Parametri!$C$6
Name WeatherApiKey: Parametri!$B$32
Name WeeklyRestDays: Parametri!$G$12:$M$18
Name ZoneKeys: Parametri!$C$12:$C$18

Sheet Copertina
A2: WORKTRAIL
A3: Plan across time zones
A4: Quick guide. This page is informational. There are no fields to fill in.
A6: 1 Set up the planner in Parameters
A7: C5: date. C6: start time. J5 / J6: margins.
A8: C7: time step, 30 or 60 minutes.
A9: Rows 12:18: configure the 7 independent columns. The first is the home column.
A10: For each column, choose a city, time zone, calendar and local hours.
A11: Days of the week: 1 = rest, 0 = activity.
A13: 2 Choose the view and print
A14: Planner: 24 hourly instants on one landscape A4 page.
A15: Extended: 48 instants on two A4 pages. The step follows Parameters C7.
... A19: 3 Read the day rules
A20: Saints / religious observances | D20: Information only.
A21: National holidays / patron | D21: Holiday: rest. Patron: where applicable.
A22: Weekend | D22: Follows the personal weekly rest rule.
A23: Leave / closures / make-up days | D23: Personal exceptions take priority.
A24: Exceptions: column 1–7, inclusive start and end dates. Choose Rest or Activity.
A25: Activity uses standard hours and margins. Exceptions take precedence over holidays and weekends.
A27: 4 Know the calendar coverage
A28: National base 2026–2028: mainland China, India, South Korea, Japan,
A29: Bangladesh, Italy, France, Norway, Sweden, the United States and Canada.
A30: No regional subdivisions. Manual patron dates remain in Calendars.
A31: VN / BY / GB retained, but not fully loaded. Estimated or future dates are not official certainties.
A33: 5 Refresh data and check the weather
A34: Data > Refresh All: 6 queries. They normally read the 6 local CSV files.
A35: Parameters B32: optional OpenWeather key. Blank = weather from Weather.csv.
A36: With a key, the Weather query calls the API for each distinct selected city.
A37: Current weather, not a forecast for the selected date. Last update is in Info.
... A40: Refresh error: the latest data is retained. Check Queries and Connections.
A41: Available | D41: Reserve | G41: Rest
A43: Moon: informational only, with no effect on hours.
A44: Saints: incomplete selection, not an official religious calendar.

Sheet Parametri
A1: Your planning panel
A2: Edit the cream cells. The Planner updates immediately. Print from the Planner sheet.
A4: 01 DAY AND DISPLAY | F4: 02 ON-CALL WITH RESERVE
B5: Home date | C5: 46289 | F5: Hours before activity | J5: 2
B6: View start | C6: 0 | F6: Hours after activity | J6: 2
B7: Extended step (min) | C7: 30
B8: Extended duration (h) | C8: =48*C7/60 -> 24 | F8: Example: 09–18, 2/2 margins → reserve 07–09 and 18–20.
A10: 03 YOUR COLUMNS · first row = home time zone
A11: No. | B11: Location | C11: Time zone | D11: Calendar | E11: From | F11: To | G11: Mon | H11: Tue | I11: Wed | J11: Thu | K11: Fri | L11: Sat | M11: Sun
A12: 1 | B12: Hanoi | C12: hanoi | D12: VN | E12: 0.20833333 | F12: 0.95833333 | G12: 0 | H12: 0 | I12: 0 | J12: 0 | K12: 0 | L12: 0 | M12: 0
A13: 2 | B13: Mumbai | C13: mumbai | D13: IN | E13: 0.375 | F13: 0.75 | G13: 0 | H13: 0 | I13: 0 | J13: 0 | K13: 0 | L13: 1 | M13: 1
A14: 3 | B14: Minsk | C14: minsk | D14: BY | E14: 0.375 | F14: 0.75 | G14: 0 | H14: 0 | I14: 0 | J14: 0 | K14: 0 | L14: 1 | M14: 1
A15: 4 | B15: Rome | C15: rome | D15: IT | E15: 0.375 | F15: 0.75 | G15: 0 | H15: 0 | I15: 0 | J15: 0 | K15: 0 | L15: 1 | M15: 1
A16: 5 | B16: London | C16: london | D16: GB-ENG | E16: 0.375 | F16: 0.75 | G16: 0 | H16: 0 | I16: 0 | J16: 0 | K16: 0 | L16: 1 | M16: 1
A17: 6 | B17: New York | C17: new-york | D17: US | E17: 0.375 | F17: 0.75 | G17: 0 | H17: 0 | I17: 0 | J17: 0 | K17: 0 | L17: 1 | M17: 1
A18: 7 | B18: Los Angeles | C18: los-angeles | D18: US | E18: 0.375 | F18: 0.75 | G18: 0 | H18: 0 | I18: 0 | J18: 0 | K18: 0 | L18: 1 | M18: 1
A20: Days of the week: 1 = rest, 0 = apply the hours. You can choose any combination.
A21: Bangladesh example: dhaka time zone, BD calendar, Fri = 1 if Friday is a rest day. Choose the other days yourself.
A22: Local patron dates are in Calendars. Leave, closures and personal make-up days go in Exceptions and take priority.
A24: 04 CALENDARS FROM FILES · Data → Refresh All
A25: Folder
A27: CSV: Cities, DST_periods, Calendars, Saints, Moon_phases, Weather. Manual changes remain separate.
A28: Refresh All rereads the CSV files. It does not monitor the disk in real time; without a refresh, the last loaded copy remains.
A29: You can edit the path if you move the files. For import errors, check Data → Queries and Connections.
A30: OPENWEATHER WEATHER - optional, manual refresh
B31: OpenWeather API key
A32: API
A34: Vuota: legge Weather.csv. Compilata: Data > Refresh All interroga le città selezionate (meteo attuale).
A35: The key is stored as plain text in the file. Do not share a copy in which you entered the key.
A36: First connection: data-source permissions / Anonymous access to OpenWeather. No automatic refresh on open.

Sheet Eccezioni
A1: Personal exceptions
A3: Exceptions take precedence over holidays, national make-up days and weekly rest days.
A4: Rest: chiusura del Thurno intero. Activity: applica gli orari e i margins della colonna.
A5: Colonna = number 1–7 in Parametri. Dal e Al sono date locali incluse. Attiva: 1 sì, 0 no.
A7: Una sola eccezione attiva per colonna e Thurno. Una sovrapposizione rende lo stato non valido.
A9: Colonna | B9: Dal | C9: Al | D9: Effetto | E9: Motivo | F9: Active 0/1 | G9: Validazione
G10: =IFERROR(IF(COUNTA(A10:F10)=0,"",IF(AND(ISNUMBER(F10),F10=0),"",IF(AND(F10=1,ISNUMBER(A10),A10=INT(A10),A10>=1,A10<=7,ISNUMBER(B10),ISNUMBER(C10),B10=INT(B10),C10=INT(C10),B10>0,C10>=B10,OR(D10="Rest",D10="Activity")),"OK","CONTROLLA"))),"CONTROLLA")
G11: =IFERROR(IF(COUNTA(A11:F11)=0,"",IF(AND(ISNUMBER(F11),F11=0),"",IF(AND(F11=1,ISNUMBER(A11),A11=INT(A11),A11>=1,A11<=7,ISNUMBER(B11),ISNUMBER(C11),B11=INT(B11),C11=INT(C11),B11>0,C11>=B11,OR(D11="Rest",D11="Activity")),"OK","CONTROLLA"))),"CONTROLLA")
G12: =IFERROR(IF(COUNTA(A12:F12)=0,"",IF(AND(ISNUMBER(F12),F12=0),"",IF(AND(F12=1,ISNUMBER(A12),A12=INT(A12),A12>=1,A12<=7,ISNUMBER(B12),ISNUMBER(C12),B12=INT(B12),C12=INT(C12),B12>0,C12>=B12,OR(D12="Rest",D12="Activity")),"OK","CONTROLLA"))),"CONTROLLA")
G13: =IFERROR(IF(COUNTA(A13:F13)=0,"",IF(AND(ISNUMBER(F13),F13=0),"",IF(AND(F13=1,ISNUMBER(A13),A13=INT(A13),A13>=1,A13<=7,ISNUMBER(B13),ISNUMBER(C13),B13=INT(B13),C13=INT(C13),B13>0,C13>=B13,OR(D13="Rest",D13="Activity")),"OK","CONTROLLA"))),"CONTROLLA")
G14: =IFERROR(IF(COUNTA(A14:F14)=0,"",IF(AND(ISNUMBER(F14),F14=0),"",IF(AND(F14=1,ISNUMBER(A14),A14=INT(A14),A14>=1,A14<=7,ISNUMBER(B14),ISNUMBER(C14),B14=INT(B14),C14=INT(C14),B14>0,C14>=B14,OR(D14="Rest",D14="Activity")),"OK","CONTROLLA"))),"CONTROLLA")
G15: =IFERROR(IF(COUNTA(A15:F15)=0,"",IF(AND(ISNUMBER(F15),F15=0),"",IF(AND(F15=1,ISNUMBER(A15),A15=INT(A15),A15>=1,A15<=7,ISNUMBER(B15),ISNUMBER(C15),B15=INT(B15),C15=INT(C15),B15>0,C15>=B15,OR(D15="Rest",D15="Activity")),"OK","CONTROLLA"))),"CONTROLLA")
G16: =IFERROR(IF(COUNTA(A16:F16)=0,"",IF(AND(ISNUMBER(F16),F16=0),"",IF(AND(F16=1,ISNUMBER(A16),A16=INT(A16),A16>=1,A16<=7,ISNUMBER(B16),ISNUMBER(C16),B16=INT(B16),C16=INT(C16),B16>0,C16>=B16,OR(D16="Rest",D16="Activity")),"OK","CONTROLLA"))),"CONTROLLA")
G17: =IFERROR(IF(COUNTA(A17:F17)=0,"",IF(AND(ISNUMBER(F17),F17=0),"",IF(AND(F17=1,ISNUMBER(A17),A17=INT(A17),A17>=1,A17<=7,ISNUMBER(B17),ISNUMBER(C17),B17=INT(B17),C17=INT(C17),B17>0,C17>=B17,OR(D17="Rest",D17="Activity")),"OK","CONTROLLA"))),"CONTROLLA")
G18: =IFERROR(IF(COUNTA(A18:F18)=0,"",IF(AND(ISNUMBER(F18),F18=0),"",IF(AND(F18=1,ISNUMBER(A18),A18=INT(A18),A18>=1,A18<=7,ISNUMBER(B18),ISNUMBER(C18),B18=INT(B18),C18=INT(C18),B18>0,C18>=B18,OR(D18="Rest",D18="Activity")),"OK","CONTROLLA"))),"CONTROLLA")
G19: =IFERROR(IF(COUNTA(A19:F19)=0,"",IF(AND(ISNUMBER(F19),F19=0),"",IF(AND(F19=1,ISNUMBER(A19),A19=INT(A19),A19>=1,A19<=7,ISNUMBER(B19),ISNUMBER(C19),B19=INT(B19),C19=INT(C19),B19>0,C19>=B19,OR(D19="Rest",D19="Activity")),"OK","CONTROLLA"))),"CONTROLLA")
G20: =IFERROR(IF(COUNTA(A20:F20)=0,"",IF(AND(ISNUMBER(F20),F20=0),"",IF(AND(F20=1,ISNUMBER(A20),A20=INT(A20),A20>=1,A20<=7,ISNUMBER(B20),ISNUMBER(C20),B20=INT(B20),C20=INT(C20),B20>0,C20>=B20,OR(D20="Rest",D20="Activity")),"OK","CONTROLLA"))),"CONTROLLA")
G21: =IFERROR(IF(COUNTA(A21:F21)=0,"",IF(AND(ISNUMBER(F21),F21=0),"",IF(AND(F21=1,ISNUMBER(A21),A21=INT(A21),A21>=1,A21<=7,ISNUMBER(B21),ISNUMBER(C21),B21=INT(B21),C21=INT(C21),B21>0,C21>=B21,OR(D21="Rest",D21="Activity")),"OK","CONTROLLA"))),"CONTROLLA")
... G109: =IFERROR(IF(COUNTA(A109:F109)=0,"",IF(AND(ISNUMBER(F109),F109=0),"",IF(AND(F109=1,ISNUMBER(A109),A109=INT(A109),A109>=1,A109<=7,ISNUMBER(B109),ISNUMBER(C109),B109=INT(B109),C109=INT(C109),B109>0,C109>=B109,OR(D109="Rest",D109="Activity")),"OK","CONTROLLA"))),"CONTROLLA")

Sheet Planner
A1: Availability and time zones
A2: ="Day in "&Planner!B8&" | "&RIGHT("0"&DAY(Planner!B4),2)&"/"&RIGHT("0"&MONTH(Planner!B4),2)&"/"&YEAR(Planner!B4)&" | "&"24 hours, 60-minute intervals" -> Day in  Hanoi | 24/09/2026 | 24 hours, 60-minute intervals
A3: =Info!B3 -> Moon at view start: 🌔 Waxing gibbous | next: 🌕 Full moon 26/09 16:49 UTC
A4: Home date | B4: =Parametri!C5 -> 46289 | C4: From | D4: =Parametri!C6 -> 0 | E4: Extended (min) | F4: =Parametri!C7 -> 30 | G4: Extended hours | H4: =48*F4/60 -> 24
A5: Reserve before (h) | B5: =Parametri!J5 -> 2 | C5: After (h) | D5: =Parametri!J6 -> 2 | E5: Availability | F5: Local hours by column
A6: AVAILABLE | C6: WITH RESERVE | E6: NOT AVAILABLE | G6: F = local holiday
A7: =IF(NOT(Calcoli!$B$8),"CONTROLLA ECCEZIONI: completa le righe attive o disattivale.",IF(NOT(Calcoli!$B$7),"CHECK PARAMETERS: invalid date, time, time zone or margins.",IF(COUNTIF(Calcoli!$B$10:$H$10,FALSE)>0,"CONTROLLA PARAMETRI: fuso, calendario, orari o riposi non validi.",IF(COUNTIF(Calcoli!$R$17:$X$88,-1)>0,"CONTROLLA ECCEZIONI/FUSI: sovrapposizione di date o dati fuori copertura.","Personal exceptions > festività > recuperi nazionali > riposi settimanali > orari.")))) -> Personal exceptions > festività > recuperi nazionali > riposi settimanali > orari.
A8: Location | B8: =IF(LEN(Calcoli!B94)=2,_xlfn.UNICHAR(127397+CODE(LEFT(Calcoli!B94,1)))&_xlfn.UNICHAR(127397+CODE(RIGHT(Calcoli!B94,1)))&" ","")&Parametri!B12 ->  Hanoi | C8: =IF(LEN(Calcoli!C94)=2,_xlfn.UNICHAR(127397+CODE(LEFT(Calcoli!C94,1)))&_xlfn.UNICHAR(127397+CODE(RIGHT(Calcoli!C94,1)))&" ","")&Parametri!B13 ->  Mumbai | D8: =IF(LEN(Calcoli!D94)=2,_xlfn.UNICHAR(127397+CODE(LEFT(Calcoli!D94,1)))&_xlfn.UNICHAR(127397+CODE(RIGHT(Calcoli!D94,1)))&" ","")&Parametri!B14 ->  Minsk | E8: =IF(LEN(Calcoli!E94)=2,_xlfn.UNICHAR(127397+CODE(LEFT(Calcoli!E94,1)))&_xlfn.UNICHAR(127397+CODE(RIGHT(Calcoli!E94,1)))&" ","")&Parametri!B15 ->  Rome | F8: =IF(LEN(Calcoli!F94)=2,_xlfn.UNICHAR(127397+CODE(LEFT(Calcoli!F94,1)))&_xlfn.UNICHAR(127397+CODE(RIGHT(Calcoli!F94,1)))&" ","")&Parametri!B16 ->  London | G8: =IF(LEN(Calcoli!G94)=2,_xlfn.UNICHAR(127397+CODE(LEFT(Calcoli!G94,1)))&_xlfn.UNICHAR(127397+CODE(RIGHT(Calcoli!G94,1)))&" ","")&Parametri!B17 ->  New York | H8: =IF(LEN(Calcoli!H94)=2,_xlfn.UNICHAR(127397+CODE(LEFT(Calcoli!H94,1)))&_xlfn.UNICHAR(127397+CODE(RIGHT(Calcoli!H94,1)))&" ","")&Parametri!B18 ->  Los Angeles
A9: Time zone (code) | B9: =Parametri!C12 -> hanoi | C9: =Parametri!C13 -> mumbai | D9: =Parametri!C14 -> minsk | E9: =Parametri!C15 -> rome | F9: =Parametri!C16 -> london | G9: =Parametri!C17 -> new-york | H9: =Parametri!C18 -> los-angeles
A10: Calendar | B10: =Parametri!D12 -> VN | C10: =Parametri!D13 -> IN | D10: =Parametri!D14 -> BY | E10: =Parametri!D15 -> IT | F10: =Parametri!D16 -> GB-ENG | G10: =Parametri!D17 -> US | H10: =Parametri!D18 -> US
A11: Activity from | B11: =Parametri!E12 -> 0.20833333 | C11: =Parametri!E13 -> 0.375 | D11: =Parametri!E14 -> 0.375 | E11: =Parametri!E15 -> 0.375 | F11: =Parametri!E16 -> 0.375 | G11: =Parametri!E17 -> 0.375 | H11: =Parametri!E18 -> 0.375
A12: Activity to | B12: =Parametri!F12 -> 0.95833333 | C12: =Parametri!F13 -> 0.75 | D12: =Parametri!F14 -> 0.75 | E12: =Parametri!F15 -> 0.75 | F12: =Parametri!F16 -> 0.75 | G12: =Parametri!F17 -> 0.75 | H12: =Parametri!F18 -> 0.75
A13: Rest days | B13: =IF(SUM(Parametri!G12:M12)=0,"—",TRIM(IF(Parametri!G12=1,"Mon ","")&IF(Parametri!H12=1,"Tue ","")&IF(Parametri!I12=1,"Wed ","")&IF(Parametri!J12=1,"Thu ","")&IF(Parametri!K12=1,"Fri ","")&IF(Parametri!L12=1,"Sat ","")&IF(Parametri!M12=1,"Sun ",""))) -> — | C13: =IF(SUM(Parametri!G13:M13)=0,"—",TRIM(IF(Parametri!G13=1,"Mon ","")&IF(Parametri!H13=1,"Tue ","")&IF(Parametri!I13=1,"Wed ","")&IF(Parametri!J13=1,"Thu ","")&IF(Parametri!K13=1,"Fri ","")&IF(Parametri!L13=1,"Sat ","")&IF(Parametri!M13=1,"Sun ",""))) -> Sat Sun | D13: =IF(SUM(Parametri!G14:M14)=0,"—",TRIM(IF(Parametri!G14=1,"Mon ","")&IF(Parametri!H14=1,"Tue ","")&IF(Parametri!I14=1,"Wed ","")&IF(Parametri!J14=1,"Thu ","")&IF(Parametri!K14=1,"Fri ","")&IF(Parametri!L14=1,"Sat ","")&IF(Parametri!M14=1,"Sun ",""))) -> Sat Sun | E13: =IF(SUM(Parametri!G15:M15)=0,"—",TRIM(IF(Parametri!G15=1,"Mon ","")&IF(Parametri!H15=1,"Tue ","")&IF(Parametri!I15=1,"Wed ","")&IF(Parametri!J15=1,"Thu ","")&IF(Parametri!K15=1,"Fri ","")&IF(Parametri!L15=1,"Sat ","")&IF(Parametri!M15=1,"Sun ",""))) -> Sat Sun | F13: =IF(SUM(Parametri!G16:M16)=0,"—",TRIM(IF(Parametri!G16=1,"Mon ","")&IF(Parametri!H16=1,"Tue ","")&IF(Parametri!I16=1,"Wed ","")&IF(Parametri!J16=1,"Thu ","")&IF(Parametri!K16=1,"Fri ","")&IF(Parametri!L16=1,"Sat ","")&IF(Parametri!M16=1,"Sun ",""))) -> Sat Sun | G13: =IF(SUM(Parametri!G17:M17)=0,"—",TRIM(IF(Parametri!G17=1,"Mon ","")&IF(Parametri!H17=1,"Tue ","")&IF(Parametri!I17=1,"Wed ","")&IF(Parametri!J17=1,"Thu ","")&IF(Parametri!K17=1,"Fri ","")&IF(Parametri!L17=1,"Sat ","")&IF(Parametri!M17=1,"Sun ",""))) -> Sat Sun | H13: =IF(SUM(Parametri!G18:M18)=0,"—",TRIM(IF(Parametri!G18=1,"Mon ","")&IF(Parametri!H18=1,"Tue ","")&IF(Parametri!I18=1,"Wed ","")&IF(Parametri!J18=1,"Thu ","")&IF(Parametri!K18=1,"Fri ","")&IF(Parametri!L18=1,"Sat ","")&IF(Parametri!M18=1,"Sun ",""))) -> Sat Sun
A14: Holiday coverage | B14: =Calcoli!B14 -> Not loaded | C14: =Calcoli!C14 -> Outside period | D14: =Calcoli!D14 -> Not loaded | E14: =Calcoli!E14 -> Outside period | F14: =Calcoli!F14 -> Outside period | G14: =Calcoli!G14 -> Outside period | H14: =Calcoli!H14 -> Outside period
A15: =Info!B4 -> Observances (info only): Blessed Virgin Mary of Mercy
A16: UTC | B16: =B8 ->  Hanoi | C16: =C8 ->  Mumbai | D16: =D8 ->  Minsk | E16: =E8 ->  Rome | F16: =F8 ->  London | G16: =G8 ->  New York | H16: =H8 ->  Los Angeles
A17: =Calcoli!A17 -> 46288.708 | B17: =Calcoli!B17 -> 46289 | C17: =Calcoli!C17 -> 46288.938 | D17: =Calcoli!D17 -> 46288.833 | E17: =Calcoli!E17 -> 46288.792 | F17: =Calcoli!F17 -> 46288.75 | G17: =Calcoli!G17 -> 46288.542 | H17: =Calcoli!H17 -> 46288.417 | J17: =Calcoli!R17 -> 1 | K17: =Calcoli!S17 -> 0 | L17: =Calcoli!T17 -> 0 | M17: =Calcoli!U17 -> 1 | N17: =Calcoli!V17 -> 1 | O17: =Calcoli!W17 -> 2 | P17: =Calcoli!X17 -> 2 | R17: =Calcoli!Z17 -> 0 | S17: =Calcoli!AA17 -> 0 | T17: =Calcoli!AB17 -> 0 | U17: =Calcoli!AC17 -> 0 | V17: =Calcoli!AD17 -> 0 | W17: =Calcoli!AE17 -> 0 | X17: =Calcoli!AF17 -> 0
A18: =Calcoli!A18 -> 46288.75 | B18: =Calcoli!B18 -> 46289.042 | C18: =Calcoli!C18 -> 46288.979 | D18: =Calcoli!D18 -> 46288.875 | E18: =Calcoli!E18 -> 46288.833 | F18: =Calcoli!F18 -> 46288.792 | G18: =Calcoli!G18 -> 46288.583 | H18: =Calcoli!H18 -> 46288.458 | J18: =Calcoli!R18 -> 0 | K18: =Calcoli!S18 -> 0 | L18: =Calcoli!T18 -> 0 | M18: =Calcoli!U18 -> 0 | N18: =Calcoli!V18 -> 1 | O18: =Calcoli!W18 -> 2 | P18: =Calcoli!X18 -> 2 | R18: =Calcoli!Z18 -> 0 | S18: =Calcoli!AA18 -> 0 | T18: =Calcoli!AB18 -> 0 | U18: =Calcoli!AC18 -> 0 | V18: =Calcoli!AD18 -> 0 | W18: =Calcoli!AE18 -> 0 | X18: =Calcoli!AF18 -> 0
A19: =Calcoli!A19 -> 46288.792 | B19: =Calcoli!B19 -> 46289.083 | C19: =Calcoli!C19 -> 46289.021 | D19: =Calcoli!D19 -> 46288.917 | E19: =Calcoli!E19 -> 46288.875 | F19: =Calcoli!F19 -> 46288.833 | G19: =Calcoli!G19 -> 46288.625 | H19: =Calcoli!H19 -> 46288.5 | J19: =Calcoli!R19 -> 0 | K19: =Calcoli!S19 -> 0 | L19: =Calcoli!T19 -> 0 | M19: =Calcoli!U19 -> 0 | N19: =Calcoli!V19 -> 0 | O19: =Calcoli!W19 -> 2 | P19: =Calcoli!X19 -> 2 | R19: =Calcoli!Z19 -> 0 | S19: =Calcoli!AA19 -> 0 | T19: =Calcoli!AB19 -> 0 | U19: =Calcoli!AC19 -> 0 | V19: =Calcoli!AD19 -> 0 | W19: =Calcoli!AE19 -> 0 | X19: =Calcoli!AF19 -> 0
A20: =Calcoli!A20 -> 46288.833 | B20: =Calcoli!B20 -> 46289.125 | C20: =Calcoli!C20 -> 46289.062 | D20: =Calcoli!D20 -> 46288.958 | E20: =Calcoli!E20 -> 46288.917 | F20: =Calcoli!F20 -> 46288.875 | G20: =Calcoli!G20 -> 46288.667 | H20: =Calcoli!H20 -> 46288.542 | J20: =Calcoli!R20 -> 1 | K20: =Calcoli!S20 -> 0 | L20: =Calcoli!T20 -> 0 | M20: =Calcoli!U20 -> 0 | N20: =Calcoli!V20 -> 0 | O20: =Calcoli!W20 -> 2 | P20: =Calcoli!X20 -> 2 | R20: =Calcoli!Z20 -> 0 | S20: =Calcoli!AA20 -> 0 | T20: =Calcoli!AB20 -> 0 | U20: =Calcoli!AC20 -> 0 | V20: =Calcoli!AD20 -> 0 | W20: =Calcoli!AE20 -> 0 | X20: =Calcoli!AF20 -> 0
A21: =Calcoli!A21 -> 46288.875 | B21: =Calcoli!B21 -> 46289.167 | C21: =Calcoli!C21 -> 46289.104 | D21: =Calcoli!D21 -> 46289 | E21: =Calcoli!E21 -> 46288.958 | F21: =Calcoli!F21 -> 46288.917 | G21: =Calcoli!G21 -> 46288.708 | H21: =Calcoli!H21 -> 46288.583 | J21: =Calcoli!R21 -> 1 | K21: =Calcoli!S21 -> 0 | L21: =Calcoli!T21 -> 0 | M21: =Calcoli!U21 -> 0 | N21: =Calcoli!V21 -> 0 | O21: =Calcoli!W21 -> 2 | P21: =Calcoli!X21 -> 2 | R21: =Calcoli!Z21 -> 0 | S21: =Calcoli!AA21 -> 0 | T21: =Calcoli!AB21 -> 0 | U21: =Calcoli!AC21 -> 0 | V21: =Calcoli!AD21 -> 0 | W21: =Calcoli!AE21 -> 0 | X21: =Calcoli!AF21 -> 0
A22: =Calcoli!A22 -> 46288.917 | B22: =Calcoli!B22 -> 46289.208 | C22: =Calcoli!C22 -> 46289.146 | D22: =Calcoli!D22 -> 46289.042 | E22: =Calcoli!E22 -> 46289 | F22: =Calcoli!F22 -> 46288.958 | G22: =Calcoli!G22 -> 46288.75 | H22: =Calcoli!H22 -> 46288.625 | J22: =Calcoli!R22 -> 2 | K22: =Calcoli!S22 -> 0 | L22: =Calcoli!T22 -> 0 | M22: =Calcoli!U22 -> 0 | N22: =Calcoli!V22 -> 0 | O22: =Calcoli!W22 -> 1 | P22: =Calcoli!X22 -> 2 | R22: =Calcoli!Z22 -> 0 | S22: =Calcoli!AA22 -> 0 | T22: =Calcoli!AB22 -> 0 | U22: =Calcoli!AC22 -> 0 | V22: =Calcoli!AD22 -> 0 | W22: =Calcoli!AE22 -> 0 | X22: =Calcoli!AF22 -> 0
A23: =Calcoli!A23 -> 46288.958 | B23: =Calcoli!B23 -> 46289.25 | C23: =Calcoli!C23 -> 46289.188 | D23: =Calcoli!D23 -> 46289.083 | E23: =Calcoli!E23 -> 46289.042 | F23: =Calcoli!F23 -> 46289 | G23: =Calcoli!G23 -> 46288.792 | H23: =Calcoli!H23 -> 46288.667 | J23: =Calcoli!R23 -> 2 | K23: =Calcoli!S23 -> 0 | L23: =Calcoli!T23 -> 0 | M23: =Calcoli!U23 -> 0 | N23: =Calcoli!V23 -> 0 | O23: =Calcoli!W23 -> 1 | P23: =Calcoli!X23 -> 2 | R23: =Calcoli!Z23 -> 0 | S23: =Calcoli!AA23 -> 0 | T23: =Calcoli!AB23 -> 0 | U23: =Calcoli!AC23 -> 0 | V23: =Calcoli!AD23 -> 0 | W23: =Calcoli!AE23 -> 0 | X23: =Calcoli!AF23 -> 0
A24: =Calcoli!A24 -> 46289 | B24: =Calcoli!B24 -> 46289.292 | C24: =Calcoli!C24 -> 46289.229 | D24: =Calcoli!D24 -> 46289.125 | E24: =Calcoli!E24 -> 46289.083 | F24: =Calcoli!F24 -> 46289.042 | G24: =Calcoli!G24 -> 46288.833 | H24: =Calcoli!H24 -> 46288.708 | J24: =Calcoli!R24 -> 2 | K24: =Calcoli!S24 -> 0 | L24: =Calcoli!T24 -> 0 | M24: =Calcoli!U24 -> 0 | N24: =Calcoli!V24 -> 0 | O24: =Calcoli!W24 -> 0 | P24: =Calcoli!X24 -> 2 | R24: =Calcoli!Z24 -> 0 | S24: =Calcoli!AA24 -> 0 | T24: =Calcoli!AB24 -> 0 | U24: =Calcoli!AC24 -> 0 | V24: =Calcoli!AD24 -> 0 | W24: =Calcoli!AE24 -> 0 | X24: =Calcoli!AF24 -> 0
A25: =Calcoli!A25 -> 46289.042 | B25: =Calcoli!B25 -> 46289.333 | C25: =Calcoli!C25 -> 46289.271 | D25: =Calcoli!D25 -> 46289.167 | E25: =Calcoli!E25 -> 46289.125 | F25: =Calcoli!F25 -> 46289.083 | G25: =Calcoli!G25 -> 46288.875 | H25: =Calcoli!H25 -> 46288.75 | J25: =Calcoli!R25 -> 2 | K25: =Calcoli!S25 -> 0 | L25: =Calcoli!T25 -> 0 | M25: =Calcoli!U25 -> 0 | N25: =Calcoli!V25 -> 0 | O25: =Calcoli!W25 -> 0 | P25: =Calcoli!X25 -> 1 | R25: =Calcoli!Z25 -> 0 | S25: =Calcoli!AA25 -> 0 | T25: =Calcoli!AB25 -> 0 | U25: =Calcoli!AC25 -> 0 | V25: =Calcoli!AD25 -> 0 | W25: =Calcoli!AE25 -> 0 | X25: =Calcoli!AF25 -> 0
A26: =Calcoli!A26 -> 46289.083 | B26: =Calcoli!B26 -> 46289.375 | C26: =Calcoli!C26 -> 46289.312 | D26: =Calcoli!D26 -> 46289.208 | E26: =Calcoli!E26 -> 46289.167 | F26: =Calcoli!F26 -> 46289.125 | G26: =Calcoli!G26 -> 46288.917 | H26: =Calcoli!H26 -> 46288.792 | J26: =Calcoli!R26 -> 2 | K26: =Calcoli!S26 -> 1 | L26: =Calcoli!T26 -> 0 | M26: =Calcoli!U26 -> 0 | N26: =Calcoli!V26 -> 0 | O26: =Calcoli!W26 -> 0 | P26: =Calcoli!X26 -> 1 | R26: =Calcoli!Z26 -> 0 | S26: =Calcoli!AA26 -> 0 | T26: =Calcoli!AB26 -> 0 | U26: =Calcoli!AC26 -> 0 | V26: =Calcoli!AD26 -> 0 | W26: =Calcoli!AE26 -> 0 | X26: =Calcoli!AF26 -> 0
A27: =Calcoli!A27 -> 46289.125 | B27: =Calcoli!B27 -> 46289.417 | C27: =Calcoli!C27 -> 46289.354 | D27: =Calcoli!D27 -> 46289.25 | E27: =Calcoli!E27 -> 46289.208 | F27: =Calcoli!F27 -> 46289.167 | G27: =Calcoli!G27 -> 46288.958 | H27: =Calcoli!H27 -> 46288.833 | J27: =Calcoli!R27 -> 2 | K27: =Calcoli!S27 -> 1 | L27: =Calcoli!T27 -> 0 | M27: =Calcoli!U27 -> 0 | N27: =Calcoli!V27 -> 0 | O27: =Calcoli!W27 -> 0 | P27: =Calcoli!X27 -> 0 | R27: =Calcoli!Z27 -> 0 | S27: =Calcoli!AA27 -> 0 | T27: =Calcoli!AB27 -> 0 | U27: =Calcoli!AC27 -> 0 | V27: =Calcoli!AD27 -> 0 | W27: =Calcoli!AE27 -> 0 | X27: =Calcoli!AF27 -> 0
A28: =Calcoli!A28 -> 46289.167 | B28: =Calcoli!B28 -> 46289.458 | C28: =Calcoli!C28 -> 46289.396 | D28: =Calcoli!D28 -> 46289.292 | E28: =Calcoli!E28 -> 46289.25 | F28: =Calcoli!F28 -> 46289.208 | G28: =Calcoli!G28 -> 46289 | H28: =Calcoli!H28 -> 46288.875 | J28: =Calcoli!R28 -> 2 | K28: =Calcoli!S28 -> 2 | L28: =Calcoli!T28 -> 1 | M28: =Calcoli!U28 -> 0 | N28: =Calcoli!V28 -> 0 | O28: =Calcoli!W28 -> 0 | P28: =Calcoli!X28 -> 0 | R28: =Calcoli!Z28 -> 0 | S28: =Calcoli!AA28 -> 0 | T28: =Calcoli!AB28 -> 0 | U28: =Calcoli!AC28 -> 0 | V28: =Calcoli!AD28 -> 0 | W28: =Calcoli!AE28 -> 0 | X28: =Calcoli!AF28 -> 0
... A40: =Calcoli!A40 -> 46289.667 | B40: =Calcoli!B40 -> 46289.958 | C40: =Calcoli!C40 -> 46289.896 | D40: =Calcoli!D40 -> 46289.792 | E40: =Calcoli!E40 -> 46289.75 | F40: =Calcoli!F40 -> 46289.708 | G40: =Calcoli!G40 -> 46289.5 | H40: =Calcoli!H40 -> 46289.375 | J40: =Calcoli!R40 -> 1 | K40: =Calcoli!S40 -> 0 | L40: =Calcoli!T40 -> 1 | M40: =Calcoli!U40 -> 1 | N40: =Calcoli!V40 -> 2 | O40: =Calcoli!W40 -> 2 | P40: =Calcoli!X40 -> 2 | R40: =Calcoli!Z40 -> 0 | S40: =Calcoli!AA40 -> 0 | T40: =Calcoli!AB40 -> 0 | U40: =Calcoli!AC40 -> 0 | V40: =Calcoli!AD40 -> 0 | W40: =Calcoli!AE40 -> 0 | X40: =Calcoli!AF40 -> 0
A41: Current weather* | B41: =IF(COUNTIF(Weather[Code],B9)=0,"Not loaded",IF(INDEX(Weather[TemperatureC],MATCH(B9,Weather[Code],0))="","Non disponibile",IF(OR(LEFT(INDEX(Weather[Status],MATCH(B9,Weather[Code],0)),5)="stale",ISNUMBER(SEARCH("aged",INDEX(Weather[Status],MATCH(B9,Weather[Code],0))))),"! ","")&Calcoli!B96&" "&ROUND(INDEX(Weather[TemperatureC],MATCH(B9,Weather[Code],0)),0)&" °C "&LEFT(INDEX(Weather[Description],MATCH(B9,Weather[Code],0)),15)&CHAR(10)&TEXT(DAY(INDEX(Weather[ObservedUtc],MATCH(B9,Weather[Code],0))),"00")&"/"&TEXT(MONTH(INDEX(Weather[ObservedUtc],MATCH(B9,Weather[Code],0))),"00")&" "&TEXT(HOUR(INDEX(Weather[ObservedUtc],MATCH(B9,Weather[Code],0))),"00")&":"&TEXT(MINUTE(INDEX(Weather[ObservedUtc],MATCH(B9,Weather[Code],0))),"00")&" UTC")) -> 26 °C few clouds 23/09 20:56 UTC | C41: =IF(COUNTIF(Weather[Code],C9)=0,"Not loaded",IF(INDEX(Weather[TemperatureC],MATCH(C9,Weather[Code],0))="","Non disponibile",IF(OR(LEFT(INDEX(Weather[Status],MATCH(C9,Weather[Code],0)),5)="stale",ISNUMBER(SEARCH("aged",INDEX(Weather[Status],MATCH(C9,Weather[Code],0))))),"! ","")&Calcoli!C96&" "&ROUND(INDEX(Weather[TemperatureC],MATCH(C9,Weather[Code],0)),0)&" °C "&LEFT(INDEX(Weather[Description],MATCH(C9,Weather[Code],0)),15)&CHAR(10)&TEXT(DAY(INDEX(Weather[ObservedUtc],MATCH(C9,Weather[Code],0))),"00")&"/"&TEXT(MONTH(INDEX(Weather[ObservedUtc],MATCH(C9,Weather[Code],0))),"00")&" "&TEXT(HOUR(INDEX(Weather[ObservedUtc],MATCH(C9,Weather[Code],0))),"00")&":"&TEXT(MINUTE(INDEX(Weather[ObservedUtc],MATCH(C9,Weather[Code],0))),"00")&" UTC")) -> 🌧️ 29 °C light rain 23/09 20:56 UTC | D41: =IF(COUNTIF(Weather[Code],D9)=0,"Not loaded",IF(INDEX(Weather[TemperatureC],MATCH(D9,Weather[Code],0))="","Non disponibile",IF(OR(LEFT(INDEX(Weather[Status],MATCH(D9,Weather[Code],0)),5)="stale",ISNUMBER(SEARCH("aged",INDEX(Weather[Status],MATCH(D9,Weather[Code],0))))),"! ","")&Calcoli!D96&" "&ROUND(INDEX(Weather[TemperatureC],MATCH(D9,Weather[Code],0)),0)&" °C "&LEFT(INDEX(Weather[Description],MATCH(D9,Weather[Code],0)),15)&CHAR(10)&TEXT(DAY(INDEX(Weather[ObservedUtc],MATCH(D9,Weather[Code],0))),"00")&"/"&TEXT(MONTH(INDEX(Weather[ObservedUtc],MATCH(D9,Weather[Code],0))),"00")&" "&TEXT(HOUR(INDEX(Weather[ObservedUtc],MATCH(D9,Weather[Code],0))),"00")&":"&TEXT(MINUTE(INDEX(Weather[ObservedUtc],MATCH(D9,Weather[Code],0))),"00")&" UTC")) -> ⛅ 9 °C scattered clouds 23/09 20:56 UTC | E41: =IF(COUNTIF(Weather[Code],E9)=0,"Not loaded",IF(INDEX(Weather[TemperatureC],MATCH(E9,Weather[Code],0))="","Non disponibile",IF(OR(LEFT(INDEX(Weather[Status],MATCH(E9,Weather[Code],0)),5)="stale",ISNUMBER(SEARCH("aged",INDEX(Weather[Status],MATCH(E9,Weather[Code],0))))),"! ","")&Calcoli!E96&" "&ROUND(INDEX(Weather[TemperatureC],MATCH(E9,Weather[Code],0)),0)&" °C "&LEFT(INDEX(Weather[Description],MATCH(E9,Weather[Code],0)),15)&CHAR(10)&TEXT(DAY(INDEX(Weather[ObservedUtc],MATCH(E9,Weather[Code],0))),"00")&"/"&TEXT(MONTH(INDEX(Weather[ObservedUtc],MATCH(E9,Weather[Code],0))),"00")&" "&TEXT(HOUR(INDEX(Weather[ObservedUtc],MATCH(E9,Weather[Code],0))),"00")&":"&TEXT(MINUTE(INDEX(Weather[ObservedUtc],MATCH(E9,Weather[Code],0))),"00")&" UTC")) -> ☀️ 21 °C clear sky 23/09 20:56 UTC | F41: =IF(COUNTIF(Weather[Code],F9)=0,"Not loaded",IF(INDEX(Weather[TemperatureC],MATCH(F9,Weather[Code],0))="","Non disponibile",IF(OR(LEFT(INDEX(Weather[Status],MATCH(F9,Weather[Code],0)),5)="stale",ISNUMBER(SEARCH("aged",INDEX(Weather[Status],MATCH(F9,Weather[Code],0))))),"! ","")&Calcoli!F96&" "&ROUND(INDEX(Weather[TemperatureC],MATCH(F9,Weather[Code],0)),0)&" °C "&LEFT(INDEX(Weather[Description],MATCH(F9,Weather[Code],0)),15)&CHAR(10)&TEXT(DAY(INDEX(Weather[ObservedUtc],MATCH(F9,Weather[Code],0))),"00")&"/"&TEXT(MONTH(INDEX(Weather[ObservedUtc],MATCH(F9,Weather[Code],0))),"00")&" "&TEXT(HOUR(INDEX(Weather[ObservedUtc],MATCH(F9,Weather[Code],0))),"00")&":"&TEXT(MINUTE(INDEX(Weather[ObservedUtc],MATCH(F9,Weather[Code],0))),"00")&" UTC")) -> ⛅ 16 °C scattered clouds 23/09 20:55 UTC | G41: =IF(COUNTIF(Weather[Code],G9)=0,"Not loaded",IF(INDEX(Weather[TemperatureC],MATCH(G9,Weather[Code],0))="","Non disponibile",IF(OR(LEFT(INDEX(Weather[Status],MATCH(G9,Weather[Code],0)),5)="stale",ISNUMBER(SEARCH("aged",INDEX(Weather[Status],MATCH(G9,Weather[Code],0))))),"! ","")&Calcoli!G96&" "&ROUND(INDEX(Weather[TemperatureC],MATCH(G9,Weather[Code],0)),0)&" °C "&LEFT(INDEX(Weather[Description],MATCH(G9,Weather[Code],0)),15)&CHAR(10)&TEXT(DAY(INDEX(Weather[ObservedUtc],MATCH(G9,Weather[Code],0))),"00")&"/"&TEXT(MONTH(INDEX(Weather[ObservedUtc],MATCH(G9,Weather[Code],0))),"00")&" "&TEXT(HOUR(INDEX(Weather[ObservedUtc],MATCH(G9,Weather[Code],0))),"00")&":"&TEXT(MINUTE(INDEX(Weather[ObservedUtc],MATCH(G9,Weather[Code],0))),"00")&" UTC")) -> 🌡️ 20 °C overcast 23/09 20:55 UTC | H41: =IF(COUNTIF(Weather[Code],H9)=0,"Not loaded",IF(INDEX(Weather[TemperatureC],MATCH(H9,Weather[Code],0))="","Non disponibile",IF(OR(LEFT(INDEX(Weather[Status],MATCH(H9,Weather[Code],0)),5)="stale",ISNUMBER(SEARCH("aged",INDEX(Weather[Status],MATCH(H9,Weather[Code],0))))),"! ","")&Calcoli!H96&" "&ROUND(INDEX(Weather[TemperatureC],MATCH(H9,Weather[Code],0)),0)&" °C "&LEFT(INDEX(Weather[Description],MATCH(H9,Weather[Code],0)),15)&CHAR(10)&TEXT(DAY(INDEX(Weather[ObservedUtc],MATCH(H9,Weather[Code],0))),"00")&"/"&TEXT(MONTH(INDEX(Weather[ObservedUtc],MATCH(H9,Weather[Code],0))),"00")&" "&TEXT(HOUR(INDEX(Weather[ObservedUtc],MATCH(H9,Weather[Code],0))),"00")&":"&TEXT(MINUTE(INDEX(Weather[ObservedUtc],MATCH(H9,Weather[Code],0))),"00")&" UTC")) -> ☀️ 29 °C clear sky 23/09 20:52 UTC
A42: F: local holiday, even when an exception applies. *Weather: latest reading and status in Info; not a forecast.

Sheet Estesa
A1: Availability and time zones — extended view
A2: ="Day in "&Planner!B8&" | "&RIGHT("0"&DAY(Planner!B4),2)&"/"&RIGHT("0"&MONTH(Planner!B4),2)&"/"&YEAR(Planner!B4)&" | "&Planner!H4&" ore, intervalli di "&Planner!F4&" minuti" -> Day in  Hanoi | 24/09/2026 | 24 hours, 30-minute intervals
A3: =Info!B3 -> Moon at view start: 🌔 Waxing gibbous | next: 🌕 Full moon 26/09 16:49 UTC
A4: Home date | B4: =Parametri!C5 -> 46289 | C4: From | D4: =Parametri!C6 -> 0 | E4: Extended (min) | F4: =Parametri!C7 -> 30 | G4: Extended hours | H4: =48*F4/60 -> 24
A5: Reserve before (h) | B5: =Parametri!J5 -> 2 | C5: After (h) | D5: =Parametri!J6 -> 2 | E5: Availability | F5: Local hours by column
A6: AVAILABLE | C6: WITH RESERVE | E6: NOT AVAILABLE | G6: F = local holiday
A7: =IF(NOT(Calcoli!$B$8),"CONTROLLA ECCEZIONI: completa le righe attive o disattivale.",IF(NOT(Calcoli!$B$7),"CHECK PARAMETERS: invalid date, time, time zone or margins.",IF(COUNTIF(Calcoli!$B$10:$H$10,FALSE)>0,"CONTROLLA PARAMETRI: fuso, calendario, orari o riposi non validi.",IF(COUNTIF(Calcoli!$R$17:$X$88,-1)>0,"CONTROLLA ECCEZIONI/FUSI: sovrapposizione di date o dati fuori copertura.","Personal exceptions > festività > recuperi nazionali > riposi settimanali > orari.")))) -> Personal exceptions > festività > recuperi nazionali > riposi settimanali > orari.
A8: Location | B8: =Planner!B8 ->  Hanoi | C8: =Planner!C8 ->  Mumbai | D8: =Planner!D8 ->  Minsk | E8: =Planner!E8 ->  Rome | F8: =Planner!F8 ->  London | G8: =Planner!G8 ->  New York | H8: =Planner!H8 ->  Los Angeles
A9: Time zone (code) | B9: =Parametri!C12 -> hanoi | C9: =Parametri!C13 -> mumbai | D9: =Parametri!C14 -> minsk | E9: =Parametri!C15 -> rome | F9: =Parametri!C16 -> london | G9: =Parametri!C17 -> new-york | H9: =Parametri!C18 -> los-angeles
A10: Calendar | B10: =Parametri!D12 -> VN | C10: =Parametri!D13 -> IN | D10: =Parametri!D14 -> BY | E10: =Parametri!D15 -> IT | F10: =Parametri!D16 -> GB-ENG | G10: =Parametri!D17 -> US | H10: =Parametri!D18 -> US
A11: Activity from | B11: =Parametri!E12 -> 0.20833333 | C11: =Parametri!E13 -> 0.375 | D11: =Parametri!E14 -> 0.375 | E11: =Parametri!E15 -> 0.375 | F11: =Parametri!E16 -> 0.375 | G11: =Parametri!E17 -> 0.375 | H11: =Parametri!E18 -> 0.375
A12: Activity to | B12: =Parametri!F12 -> 0.95833333 | C12: =Parametri!F13 -> 0.75 | D12: =Parametri!F14 -> 0.75 | E12: =Parametri!F15 -> 0.75 | F12: =Parametri!F16 -> 0.75 | G12: =Parametri!F17 -> 0.75 | H12: =Parametri!F18 -> 0.75
A13: Rest days | B13: =IF(SUM(Parametri!G12:M12)=0,"—",TRIM(IF(Parametri!G12=1,"Mon ","")&IF(Parametri!H12=1,"Tue ","")&IF(Parametri!I12=1,"Wed ","")&IF(Parametri!J12=1,"Thu ","")&IF(Parametri!K12=1,"Fri ","")&IF(Parametri!L12=1,"Sat ","")&IF(Parametri!M12=1,"Sun ",""))) -> — | C13: =IF(SUM(Parametri!G13:M13)=0,"—",TRIM(IF(Parametri!G13=1,"Mon ","")&IF(Parametri!H13=1,"Tue ","")&IF(Parametri!I13=1,"Wed ","")&IF(Parametri!J13=1,"Thu ","")&IF(Parametri!K13=1,"Fri ","")&IF(Parametri!L13=1,"Sat ","")&IF(Parametri!M13=1,"Sun ",""))) -> Sat Sun | D13: =IF(SUM(Parametri!G14:M14)=0,"—",TRIM(IF(Parametri!G14=1,"Mon ","")&IF(Parametri!H14=1,"Tue ","")&IF(Parametri!I14=1,"Wed ","")&IF(Parametri!J14=1,"Thu ","")&IF(Parametri!K14=1,"Fri ","")&IF(Parametri!L14=1,"Sat ","")&IF(Parametri!M14=1,"Sun ",""))) -> Sat Sun | E13: =IF(SUM(Parametri!G15:M15)=0,"—",TRIM(IF(Parametri!G15=1,"Mon ","")&IF(Parametri!H15=1,"Tue ","")&IF(Parametri!I15=1,"Wed ","")&IF(Parametri!J15=1,"Thu ","")&IF(Parametri!K15=1,"Fri ","")&IF(Parametri!L15=1,"Sat ","")&IF(Parametri!M15=1,"Sun ",""))) -> Sat Sun | F13: =IF(SUM(Parametri!G16:M16)=0,"—",TRIM(IF(Parametri!G16=1,"Mon ","")&IF(Parametri!H16=1,"Tue ","")&IF(Parametri!I16=1,"Wed ","")&IF(Parametri!J16=1,"Thu ","")&IF(Parametri!K16=1,"Fri ","")&IF(Parametri!L16=1,"Sat ","")&IF(Parametri!M16=1,"Sun ",""))) -> Sat Sun | G13: =IF(SUM(Parametri!G17:M17)=0,"—",TRIM(IF(Parametri!G17=1,"Mon ","")&IF(Parametri!H17=1,"Tue ","")&IF(Parametri!I17=1,"Wed ","")&IF(Parametri!J17=1,"Thu ","")&IF(Parametri!K17=1,"Fri ","")&IF(Parametri!L17=1,"Sat ","")&IF(Parametri!M17=1,"Sun ",""))) -> Sat Sun | H13: =IF(SUM(Parametri!G18:M18)=0,"—",TRIM(IF(Parametri!G18=1,"Mon ","")&IF(Parametri!H18=1,"Tue ","")&IF(Parametri!I18=1,"Wed ","")&IF(Parametri!J18=1,"Thu ","")&IF(Parametri!K18=1,"Fri ","")&IF(Parametri!L18=1,"Sat ","")&IF(Parametri!M18=1,"Sun ",""))) -> Sat Sun
A14: Holiday coverage | B14: =Calcoli!B15 -> Not loaded | C14: =Calcoli!C15 -> Outside period | D14: =Calcoli!D15 -> Not loaded | E14: =Calcoli!E15 -> Outside period | F14: =Calcoli!F15 -> Outside period | G14: =Calcoli!G15 -> Outside period | H14: =Calcoli!H15 -> Outside period
A15: =Info!B4 -> Observances (info only): Blessed Virgin Mary of Mercy
A16: UTC | B16: =B8 ->  Hanoi | C16: =C8 ->  Mumbai | D16: =D8 ->  Minsk | E16: =E8 ->  Rome | F16: =F8 ->  London | G16: =G8 ->  New York | H16: =H8 ->  Los Angeles
A17: =Calcoli!A41 -> 46288.708 | B17: =Calcoli!B41 -> 46289 | C17: =Calcoli!C41 -> 46288.938 | D17: =Calcoli!D41 -> 46288.833 | E17: =Calcoli!E41 -> 46288.792 | F17: =Calcoli!F41 -> 46288.75 | G17: =Calcoli!G41 -> 46288.542 | H17: =Calcoli!H41 -> 46288.417 | J17: =Calcoli!R41 -> 1 | K17: =Calcoli!S41 -> 0 | L17: =Calcoli!T41 -> 0 | M17: =Calcoli!U41 -> 1 | N17: =Calcoli!V41 -> 1 | O17: =Calcoli!W41 -> 2 | P17: =Calcoli!X41 -> 2 | R17: =Calcoli!Z41 -> 0 | S17: =Calcoli!AA41 -> 0 | T17: =Calcoli!AB41 -> 0 | U17: =Calcoli!AC41 -> 0 | V17: =Calcoli!AD41 -> 0 | W17: =Calcoli!AE41 -> 0 | X17: =Calcoli!AF41 -> 0
A18: =Calcoli!A42 -> 46288.729 | B18: =Calcoli!B42 -> 46289.021 | C18: =Calcoli!C42 -> 46288.958 | D18: =Calcoli!D42 -> 46288.854 | E18: =Calcoli!E42 -> 46288.812 | F18: =Calcoli!F42 -> 46288.771 | G18: =Calcoli!G42 -> 46288.562 | H18: =Calcoli!H42 -> 46288.438 | J18: =Calcoli!R42 -> 1 | K18: =Calcoli!S42 -> 0 | L18: =Calcoli!T42 -> 0 | M18: =Calcoli!U42 -> 1 | N18: =Calcoli!V42 -> 1 | O18: =Calcoli!W42 -> 2 | P18: =Calcoli!X42 -> 2 | R18: =Calcoli!Z42 -> 0 | S18: =Calcoli!AA42 -> 0 | T18: =Calcoli!AB42 -> 0 | U18: =Calcoli!AC42 -> 0 | V18: =Calcoli!AD42 -> 0 | W18: =Calcoli!AE42 -> 0 | X18: =Calcoli!AF42 -> 0
A19: =Calcoli!A43 -> 46288.75 | B19: =Calcoli!B43 -> 46289.042 | C19: =Calcoli!C43 -> 46288.979 | D19: =Calcoli!D43 -> 46288.875 | E19: =Calcoli!E43 -> 46288.833 | F19: =Calcoli!F43 -> 46288.792 | G19: =Calcoli!G43 -> 46288.583 | H19: =Calcoli!H43 -> 46288.458 | J19: =Calcoli!R43 -> 0 | K19: =Calcoli!S43 -> 0 | L19: =Calcoli!T43 -> 0 | M19: =Calcoli!U43 -> 0 | N19: =Calcoli!V43 -> 1 | O19: =Calcoli!W43 -> 2 | P19: =Calcoli!X43 -> 2 | R19: =Calcoli!Z43 -> 0 | S19: =Calcoli!AA43 -> 0 | T19: =Calcoli!AB43 -> 0 | U19: =Calcoli!AC43 -> 0 | V19: =Calcoli!AD43 -> 0 | W19: =Calcoli!AE43 -> 0 | X19: =Calcoli!AF43 -> 0
A20: =Calcoli!A44 -> 46288.771 | B20: =Calcoli!B44 -> 46289.062 | C20: =Calcoli!C44 -> 46289 | D20: =Calcoli!D44 -> 46288.896 | E20: =Calcoli!E44 -> 46288.854 | F20: =Calcoli!F44 -> 46288.812 | G20: =Calcoli!G44 -> 46288.604 | H20: =Calcoli!H44 -> 46288.479 | J20: =Calcoli!R44 -> 0 | K20: =Calcoli!S44 -> 0 | L20: =Calcoli!T44 -> 0 | M20: =Calcoli!U44 -> 0 | N20: =Calcoli!V44 -> 1 | O20: =Calcoli!W44 -> 2 | P20: =Calcoli!X44 -> 2 | R20: =Calcoli!Z44 -> 0 | S20: =Calcoli!AA44 -> 0 | T20: =Calcoli!AB44 -> 0 | U20: =Calcoli!AC44 -> 0 | V20: =Calcoli!AD44 -> 0 | W20: =Calcoli!AE44 -> 0 | X20: =Calcoli!AF44 -> 0
A21: =Calcoli!A45 -> 46288.792 | B21: =Calcoli!B45 -> 46289.083 | C21: =Calcoli!C45 -> 46289.021 | D21: =Calcoli!D45 -> 46288.917 | E21: =Calcoli!E45 -> 46288.875 | F21: =Calcoli!F45 -> 46288.833 | G21: =Calcoli!G45 -> 46288.625 | H21: =Calcoli!H45 -> 46288.5 | J21: =Calcoli!R45 -> 0 | K21: =Calcoli!S45 -> 0 | L21: =Calcoli!T45 -> 0 | M21: =Calcoli!U45 -> 0 | N21: =Calcoli!V45 -> 0 | O21: =Calcoli!W45 -> 2 | P21: =Calcoli!X45 -> 2 | R21: =Calcoli!Z45 -> 0 | S21: =Calcoli!AA45 -> 0 | T21: =Calcoli!AB45 -> 0 | U21: =Calcoli!AC45 -> 0 | V21: =Calcoli!AD45 -> 0 | W21: =Calcoli!AE45 -> 0 | X21: =Calcoli!AF45 -> 0
A22: =Calcoli!A46 -> 46288.812 | B22: =Calcoli!B46 -> 46289.104 | C22: =Calcoli!C46 -> 46289.042 | D22: =Calcoli!D46 -> 46288.938 | E22: =Calcoli!E46 -> 46288.896 | F22: =Calcoli!F46 -> 46288.854 | G22: =Calcoli!G46 -> 46288.646 | H22: =Calcoli!H46 -> 46288.521 | J22: =Calcoli!R46 -> 0 | K22: =Calcoli!S46 -> 0 | L22: =Calcoli!T46 -> 0 | M22: =Calcoli!U46 -> 0 | N22: =Calcoli!V46 -> 0 | O22: =Calcoli!W46 -> 2 | P22: =Calcoli!X46 -> 2 | R22: =Calcoli!Z46 -> 0 | S22: =Calcoli!AA46 -> 0 | T22: =Calcoli!AB46 -> 0 | U22: =Calcoli!AC46 -> 0 | V22: =Calcoli!AD46 -> 0 | W22: =Calcoli!AE46 -> 0 | X22: =Calcoli!AF46 -> 0
A23: =Calcoli!A47 -> 46288.833 | B23: =Calcoli!B47 -> 46289.125 | C23: =Calcoli!C47 -> 46289.062 | D23: =Calcoli!D47 -> 46288.958 | E23: =Calcoli!E47 -> 46288.917 | F23: =Calcoli!F47 -> 46288.875 | G23: =Calcoli!G47 -> 46288.667 | H23: =Calcoli!H47 -> 46288.542 | J23: =Calcoli!R47 -> 1 | K23: =Calcoli!S47 -> 0 | L23: =Calcoli!T47 -> 0 | M23: =Calcoli!U47 -> 0 | N23: =Calcoli!V47 -> 0 | O23: =Calcoli!W47 -> 2 | P23: =Calcoli!X47 -> 2 | R23: =Calcoli!Z47 -> 0 | S23: =Calcoli!AA47 -> 0 | T23: =Calcoli!AB47 -> 0 | U23: =Calcoli!AC47 -> 0 | V23: =Calcoli!AD47 -> 0 | W23: =Calcoli!AE47 -> 0 | X23: =Calcoli!AF47 -> 0
A24: =Calcoli!A48 -> 46288.854 | B24: =Calcoli!B48 -> 46289.146 | C24: =Calcoli!C48 -> 46289.083 | D24: =Calcoli!D48 -> 46288.979 | E24: =Calcoli!E48 -> 46288.938 | F24: =Calcoli!F48 -> 46288.896 | G24: =Calcoli!G48 -> 46288.688 | H24: =Calcoli!H48 -> 46288.562 | J24: =Calcoli!R48 -> 1 | K24: =Calcoli!S48 -> 0 | L24: =Calcoli!T48 -> 0 | M24: =Calcoli!U48 -> 0 | N24: =Calcoli!V48 -> 0 | O24: =Calcoli!W48 -> 2 | P24: =Calcoli!X48 -> 2 | R24: =Calcoli!Z48 -> 0 | S24: =Calcoli!AA48 -> 0 | T24: =Calcoli!AB48 -> 0 | U24: =Calcoli!AC48 -> 0 | V24: =Calcoli!AD48 -> 0 | W24: =Calcoli!AE48 -> 0 | X24: =Calcoli!AF48 -> 0
A25: =Calcoli!A49 -> 46288.875 | B25: =Calcoli!B49 -> 46289.167 | C25: =Calcoli!C49 -> 46289.104 | D25: =Calcoli!D49 -> 46289 | E25: =Calcoli!E49 -> 46288.958 | F25: =Calcoli!F49 -> 46288.917 | G25: =Calcoli!G49 -> 46288.708 | H25: =Calcoli!H49 -> 46288.583 | J25: =Calcoli!R49 -> 1 | K25: =Calcoli!S49 -> 0 | L25: =Calcoli!T49 -> 0 | M25: =Calcoli!U49 -> 0 | N25: =Calcoli!V49 -> 0 | O25: =Calcoli!W49 -> 2 | P25: =Calcoli!X49 -> 2 | R25: =Calcoli!Z49 -> 0 | S25: =Calcoli!AA49 -> 0 | T25: =Calcoli!AB49 -> 0 | U25: =Calcoli!AC49 -> 0 | V25: =Calcoli!AD49 -> 0 | W25: =Calcoli!AE49 -> 0 | X25: =Calcoli!AF49 -> 0
A26: =Calcoli!A50 -> 46288.896 | B26: =Calcoli!B50 -> 46289.188 | C26: =Calcoli!C50 -> 46289.125 | D26: =Calcoli!D50 -> 46289.021 | E26: =Calcoli!E50 -> 46288.979 | F26: =Calcoli!F50 -> 46288.938 | G26: =Calcoli!G50 -> 46288.729 | H26: =Calcoli!H50 -> 46288.604 | J26: =Calcoli!R50 -> 1 | K26: =Calcoli!S50 -> 0 | L26: =Calcoli!T50 -> 0 | M26: =Calcoli!U50 -> 0 | N26: =Calcoli!V50 -> 0 | O26: =Calcoli!W50 -> 2 | P26: =Calcoli!X50 -> 2 | R26: =Calcoli!Z50 -> 0 | S26: =Calcoli!AA50 -> 0 | T26: =Calcoli!AB50 -> 0 | U26: =Calcoli!AC50 -> 0 | V26: =Calcoli!AD50 -> 0 | W26: =Calcoli!AE50 -> 0 | X26: =Calcoli!AF50 -> 0
A27: =Calcoli!A51 -> 46288.917 | B27: =Calcoli!B51 -> 46289.208 | C27: =Calcoli!C51 -> 46289.146 | D27: =Calcoli!D51 -> 46289.042 | E27: =Calcoli!E51 -> 46289 | F27: =Calcoli!F51 -> 46288.958 | G27: =Calcoli!G51 -> 46288.75 | H27: =Calcoli!H51 -> 46288.625 | J27: =Calcoli!R51 -> 2 | K27: =Calcoli!S51 -> 0 | L27: =Calcoli!T51 -> 0 | M27: =Calcoli!U51 -> 0 | N27: =Calcoli!V51 -> 0 | O27: =Calcoli!W51 -> 1 | P27: =Calcoli!X51 -> 2 | R27: =Calcoli!Z51 -> 0 | S27: =Calcoli!AA51 -> 0 | T27: =Calcoli!AB51 -> 0 | U27: =Calcoli!AC51 -> 0 | V27: =Calcoli!AD51 -> 0 | W27: =Calcoli!AE51 -> 0 | X27: =Calcoli!AF51 -> 0
A28: =Calcoli!A52 -> 46288.938 | B28: =Calcoli!B52 -> 46289.229 | C28: =Calcoli!C52 -> 46289.167 | D28: =Calcoli!D52 -> 46289.062 | E28: =Calcoli!E52 -> 46289.021 | F28: =Calcoli!F52 -> 46288.979 | G28: =Calcoli!G52 -> 46288.771 | H28: =Calcoli!H52 -> 46288.646 | J28: =Calcoli!R52 -> 2 | K28: =Calcoli!S52 -> 0 | L28: =Calcoli!T52 -> 0 | M28: =Calcoli!U52 -> 0 | N28: =Calcoli!V52 -> 0 | O28: =Calcoli!W52 -> 1 | P28: =Calcoli!X52 -> 2 | R28: =Calcoli!Z52 -> 0 | S28: =Calcoli!AA52 -> 0 | T28: =Calcoli!AB52 -> 0 | U28: =Calcoli!AC52 -> 0 | V28: =Calcoli!AD52 -> 0 | W28: =Calcoli!AE52 -> 0 | X28: =Calcoli!AF52 -> 0
... A64: =Calcoli!A88 -> 46289.688 | B64: =Calcoli!B88 -> 46289.979 | C64: =Calcoli!C88 -> 46289.917 | D64: =Calcoli!D88 -> 46289.812 | E64: =Calcoli!E88 -> 46289.771 | F64: =Calcoli!F88 -> 46289.729 | G64: =Calcoli!G88 -> 46289.521 | H64: =Calcoli!H88 -> 46289.396 | J64: =Calcoli!R88 -> 1 | K64: =Calcoli!S88 -> 0 | L64: =Calcoli!T88 -> 1 | M64: =Calcoli!U88 -> 1 | N64: =Calcoli!V88 -> 2 | O64: =Calcoli!W88 -> 2 | P64: =Calcoli!X88 -> 2 | R64: =Calcoli!Z88 -> 0 | S64: =Calcoli!AA88 -> 0 | T64: =Calcoli!AB88 -> 0 | U64: =Calcoli!AC88 -> 0 | V64: =Calcoli!AD88 -> 0 | W64: =Calcoli!AE88 -> 0 | X64: =Calcoli!AF88 -> 0
A65: Current weather* | B65: =IF(COUNTIF(Weather[Code],B9)=0,"Not loaded",IF(INDEX(Weather[TemperatureC],MATCH(B9,Weather[Code],0))="","Non disponibile",IF(OR(LEFT(INDEX(Weather[Status],MATCH(B9,Weather[Code],0)),5)="stale",ISNUMBER(SEARCH("aged",INDEX(Weather[Status],MATCH(B9,Weather[Code],0))))),"! ","")&Calcoli!B96&" "&ROUND(INDEX(Weather[TemperatureC],MATCH(B9,Weather[Code],0)),0)&" °C "&LEFT(INDEX(Weather[Description],MATCH(B9,Weather[Code],0)),15)&CHAR(10)&TEXT(DAY(INDEX(Weather[ObservedUtc],MATCH(B9,Weather[Code],0))),"00")&"/"&TEXT(MONTH(INDEX(Weather[ObservedUtc],MATCH(B9,Weather[Code],0))),"00")&" "&TEXT(HOUR(INDEX(Weather[ObservedUtc],MATCH(B9,Weather[Code],0))),"00")&":"&TEXT(MINUTE(INDEX(Weather[ObservedUtc],MATCH(B9,Weather[Code],0))),"00")&" UTC")) -> 26 °C few clouds 23/09 20:56 UTC | C65: =IF(COUNTIF(Weather[Code],C9)=0,"Not loaded",IF(INDEX(Weather[TemperatureC],MATCH(C9,Weather[Code],0))="","Non disponibile",IF(OR(LEFT(INDEX(Weather[Status],MATCH(C9,Weather[Code],0)),5)="stale",ISNUMBER(SEARCH("aged",INDEX(Weather[Status],MATCH(C9,Weather[Code],0))))),"! ","")&Calcoli!C96&" "&ROUND(INDEX(Weather[TemperatureC],MATCH(C9,Weather[Code],0)),0)&" °C "&LEFT(INDEX(Weather[Description],MATCH(C9,Weather[Code],0)),15)&CHAR(10)&TEXT(DAY(INDEX(Weather[ObservedUtc],MATCH(C9,Weather[Code],0))),"00")&"/"&TEXT(MONTH(INDEX(Weather[ObservedUtc],MATCH(C9,Weather[Code],0))),"00")&" "&TEXT(HOUR(INDEX(Weather[ObservedUtc],MATCH(C9,Weather[Code],0))),"00")&":"&TEXT(MINUTE(INDEX(Weather[ObservedUtc],MATCH(C9,Weather[Code],0))),"00")&" UTC")) -> 🌧️ 29 °C light rain 23/09 20:56 UTC | D65: =IF(COUNTIF(Weather[Code],D9)=0,"Not loaded",IF(INDEX(Weather[TemperatureC],MATCH(D9,Weather[Code],0))="","Non disponibile",IF(OR(LEFT(INDEX(Weather[Status],MATCH(D9,Weather[Code],0)),5)="stale",ISNUMBER(SEARCH("aged",INDEX(Weather[Status],MATCH(D9,Weather[Code],0))))),"! ","")&Calcoli!D96&" "&ROUND(INDEX(Weather[TemperatureC],MATCH(D9,Weather[Code],0)),0)&" °C "&LEFT(INDEX(Weather[Description],MATCH(D9,Weather[Code],0)),15)&CHAR(10)&TEXT(DAY(INDEX(Weather[ObservedUtc],MATCH(D9,Weather[Code],0))),"00")&"/"&TEXT(MONTH(INDEX(Weather[ObservedUtc],MATCH(D9,Weather[Code],0))),"00")&" "&TEXT(HOUR(INDEX(Weather[ObservedUtc],MATCH(D9,Weather[Code],0))),"00")&":"&TEXT(MINUTE(INDEX(Weather[ObservedUtc],MATCH(D9,Weather[Code],0))),"00")&" UTC")) -> ⛅ 9 °C scattered clouds 23/09 20:56 UTC | E65: =IF(COUNTIF(Weather[Code],E9)=0,"Not loaded",IF(INDEX(Weather[TemperatureC],MATCH(E9,Weather[Code],0))="","Non disponibile",IF(OR(LEFT(INDEX(Weather[Status],MATCH(E9,Weather[Code],0)),5)="stale",ISNUMBER(SEARCH("aged",INDEX(Weather[Status],MATCH(E9,Weather[Code],0))))),"! ","")&Calcoli!E96&" "&ROUND(INDEX(Weather[TemperatureC],MATCH(E9,Weather[Code],0)),0)&" °C "&LEFT(INDEX(Weather[Description],MATCH(E9,Weather[Code],0)),15)&CHAR(10)&TEXT(DAY(INDEX(Weather[ObservedUtc],MATCH(E9,Weather[Code],0))),"00")&"/"&TEXT(MONTH(INDEX(Weather[ObservedUtc],MATCH(E9,Weather[Code],0))),"00")&" "&TEXT(HOUR(INDEX(Weather[ObservedUtc],MATCH(E9,Weather[Code],0))),"00")&":"&TEXT(MINUTE(INDEX(Weather[ObservedUtc],MATCH(E9,Weather[Code],0))),"00")&" UTC")) -> ☀️ 21 °C clear sky 23/09 20:56 UTC | F65: =IF(COUNTIF(Weather[Code],F9)=0,"Not loaded",IF(INDEX(Weather[TemperatureC],MATCH(F9,Weather[Code],0))="","Non disponibile",IF(OR(LEFT(INDEX(Weather[Status],MATCH(F9,Weather[Code],0)),5)="stale",ISNUMBER(SEARCH("aged",INDEX(Weather[Status],MATCH(F9,Weather[Code],0))))),"! ","")&Calcoli!F96&" "&ROUND(INDEX(Weather[TemperatureC],MATCH(F9,Weather[Code],0)),0)&" °C "&LEFT(INDEX(Weather[Description],MATCH(F9,Weather[Code],0)),15)&CHAR(10)&TEXT(DAY(INDEX(Weather[ObservedUtc],MATCH(F9,Weather[Code],0))),"00")&"/"&TEXT(MONTH(INDEX(Weather[ObservedUtc],MATCH(F9,Weather[Code],0))),"00")&" "&TEXT(HOUR(INDEX(Weather[ObservedUtc],MATCH(F9,Weather[Code],0))),"00")&":"&TEXT(MINUTE(INDEX(Weather[ObservedUtc],MATCH(F9,Weather[Code],0))),"00")&" UTC")) -> ⛅ 16 °C scattered clouds 23/09 20:55 UTC | G65: =IF(COUNTIF(Weather[Code],G9)=0,"Not loaded",IF(INDEX(Weather[TemperatureC],MATCH(G9,Weather[Code],0))="","Non disponibile",IF(OR(LEFT(INDEX(Weather[Status],MATCH(G9,Weather[Code],0)),5)="stale",ISNUMBER(SEARCH("aged",INDEX(Weather[Status],MATCH(G9,Weather[Code],0))))),"! ","")&Calcoli!G96&" "&ROUND(INDEX(Weather[TemperatureC],MATCH(G9,Weather[Code],0)),0)&" °C "&LEFT(INDEX(Weather[Description],MATCH(G9,Weather[Code],0)),15)&CHAR(10)&TEXT(DAY(INDEX(Weather[ObservedUtc],MATCH(G9,Weather[Code],0))),"00")&"/"&TEXT(MONTH(INDEX(Weather[ObservedUtc],MATCH(G9,Weather[Code],0))),"00")&" "&TEXT(HOUR(INDEX(Weather[ObservedUtc],MATCH(G9,Weather[Code],0))),"00")&":"&TEXT(MINUTE(INDEX(Weather[ObservedUtc],MATCH(G9,Weather[Code],0))),"00")&" UTC")) -> 🌡️ 20 °C overcast 23/09 20:55 UTC | H65: =IF(COUNTIF(Weather[Code],H9)=0,"Not loaded",IF(INDEX(Weather[TemperatureC],MATCH(H9,Weather[Code],0))="","Non disponibile",IF(OR(LEFT(INDEX(Weather[Status],MATCH(H9,Weather[Code],0)),5)="stale",ISNUMBER(SEARCH("aged",INDEX(Weather[Status],MATCH(H9,Weather[Code],0))))),"! ","")&Calcoli!H96&" "&ROUND(INDEX(Weather[TemperatureC],MATCH(H9,Weather[Code],0)),0)&" °C "&LEFT(INDEX(Weather[Description],MATCH(H9,Weather[Code],0)),15)&CHAR(10)&TEXT(DAY(INDEX(Weather[ObservedUtc],MATCH(H9,Weather[Code],0))),"00")&"/"&TEXT(MONTH(INDEX(Weather[ObservedUtc],MATCH(H9,Weather[Code],0))),"00")&" "&TEXT(HOUR(INDEX(Weather[ObservedUtc],MATCH(H9,Weather[Code],0))),"00")&":"&TEXT(MINUTE(INDEX(Weather[ObservedUtc],MATCH(H9,Weather[Code],0))),"00")&" UTC")) -> ☀️ 29 °C clear sky 23/09 20:52 UTC
A66: F: local holiday, even when an exception applies. *Weather: latest reading and status in Info; not a forecast.

Sheet Calendari
A1: Holiday calendars
A2: Outside period 2026-2028. Dati = 1 indica dati presenti, non certifica completezza o applicabilità aziendale.
A3: Patroni locali: aggiungi date sotto con il calendario applicabile. Ferie e recuperi personali: usa Eccezioni.
A5: Codice | B5: Paese / reThun | C5: Dal | D5: Al | E5: Data 0/1 | F5: Source / notes
A6: Nessuno | B6: Holidays disattivate | C6: 46023 | D6: 47118 | E6: 1 | F6: No calendar applied.
A7: VN | B7: Vietnam | E7: 0 | F7: Inserire calendario ufficiale nazionale/locale.
A8: IN | B8: India | C8: 46023 | D8: 47118 | E8: 1 | F8: Nazionale; senza suddivisioni. holidays holidays 0.105; snapshot, non verifica ufficiale completa.
A9: BY | B9: Bielorussia | E9: 0 | F9: Inserire calendario ufficiale.
A10: IT | B10: Italia | C10: 46023 | D10: 47118 | E10: 1 | F10: Nazionale; senza suddivisioni. holidays holidays 0.105; snapshot, non verifica ufficiale completa.
A11: GB-ENG | B11: Inghilterra e Galles | C11: 46023 | D11: 47118 | E11: 1 | F11: https://www.gov.uk/bank-holidays
A12: US | B12: Stati Uniti | C12: 46023 | D12: 47118 | E12: 1 | F12: Nazionale; senza suddivisioni. holidays holidays 0.105; snapshot, non verifica ufficiale completa.
A13: BD | B13: Bangladesh | C13: 46023 | D13: 47118 | E13: 1 | F13: Nazionale; senza suddivisioni. holidays holidays 0.105; snapshot, non verifica ufficiale completa.
A14: CN | B14: Cina continentale | C14: 46023 | D14: 47118 | E14: 1 | F14: Nazionale; senza suddivisioni. holidays holidays 0.105; snapshot, non verifica ufficiale completa.
A15: KR | B15: Corea del Sud | C15: 46023 | D15: 47118 | E15: 1 | F15: Nazionale; senza suddivisioni. holidays holidays 0.105; snapshot, non verifica ufficiale completa.
A16: JP | B16: Giappone | C16: 46023 | D16: 47118 | E16: 1 | F16: Nazionale; senza suddivisioni. holidays holidays 0.105; snapshot, non verifica ufficiale completa.
A17: FR | B17: Francia | C17: 46023 | D17: 47118 | E17: 1 | F17: Nazionale; senza suddivisioni. holidays holidays 0.105; snapshot, non verifica ufficiale completa.
A18: NO | B18: Norvegia | C18: 46023 | D18: 47118 | E18: 1 | F18: Nazionale; senza suddivisioni. holidays holidays 0.105; snapshot, non verifica ufficiale completa.
A19: SE | B19: Svezia | C19: 46023 | D19: 47118 | E19: 1 | F19: Public + de_facto; domeniche ricorrenti escluse, gestite in Parametri. holidays holidays 0.105; snapshot, non verifica ufficiale completa.
A20: CA | B20: Canada | C20: 46023 | D20: 47118 | E20: 1 | F20: Base federale (public + government); non tutte le aziende. holidays holidays 0.105; snapshot, non verifica ufficiale completa.
A27: DATE MANUALI: patroni o altre festività applicabili. Attiva = 1 chiude il Thurno; Eccezioni può derogare.
A29: Calendar | B29: Local date | C29: Holidays / chiusura | D29: Active 0/1 | E29: Fonte

Sheet Da_file
A1: Holidays importate dal CSV
A2: Non modificare questa tabella: Refresh tutto la sostituisce con il contenuto del file indicato in Parametri.
A3: HOLIDAY = festività; WORKDAY = recupero nazionale. Status distingue stime e base da verificare. Personalizzazioni in Calendari/Eccezioni.
A5: Calendar | B5: Date | C5: Name | D5: Active | E5: Source | F5: Kind | G5: Status | H5: Version | I5: Updated
A6: BD | B6: 46057 | C6: Mid-Sha'ban | D6: 1 | E6: https://github.com/vacanza/holidays/blob/v0.105/holidays/countries/bangladesh.py | F6: HOLIDAY | G6: Da regole; non verificata singolarmente | H6: 0.105 | I6: 2026-09-23T20:51:39+00:00
A7: BD | B7: 46074 | C7: Tuetyrs' Day and International Mother Language Day | D7: 1 | E7: https://github.com/vacanza/holidays/blob/v0.105/holidays/countries/bangladesh.py | F7: HOLIDAY | G7: Da regole; non verificata singolarmente | H7: 0.105 | I7: 2026-09-23T20:51:39+00:00
A8: BD | B8: 46098 | C8: Laylat al-Qadr | D8: 1 | E8: https://github.com/vacanza/holidays/blob/v0.105/holidays/countries/bangladesh.py | F8: HOLIDAY | G8: Da regole; non verificata singolarmente | H8: 0.105 | I8: 2026-09-23T20:51:39+00:00
A9: BD | B9: 46101 | C9: Jumu'atul-Wida | D9: 1 | E9: https://github.com/vacanza/holidays/blob/v0.105/holidays/countries/bangladesh.py | F9: HOLIDAY | G9: Da regole; non verificata singolarmente | H9: 0.105 | I9: 2026-09-23T20:51:39+00:00
A10: BD | B10: 46102 | C10: Eid al-Fitr | D10: 1 | E10: https://github.com/vacanza/holidays/blob/v0.105/holidays/countries/bangladesh.py | F10: HOLIDAY | G10: Da regole; non verificata singolarmente | H10: 0.105 | I10: 2026-09-23T20:51:39+00:00
A11: BD | B11: 46103 | C11: Eid al-Fitr | D11: 1 | E11: https://github.com/vacanza/holidays/blob/v0.105/holidays/countries/bangladesh.py | F11: HOLIDAY | G11: Da regole; non verificata singolarmente | H11: 0.105 | I11: 2026-09-23T20:51:39+00:00
A12: BD | B12: 46104 | C12: Eid al-Fitr | D12: 1 | E12: https://github.com/vacanza/holidays/blob/v0.105/holidays/countries/bangladesh.py | F12: HOLIDAY | G12: Da regole; non verificata singolarmente | H12: 0.105 | I12: 2026-09-23T20:51:39+00:00
A13: BD | B13: 46107 | C13: Independence Day | D13: 1 | E13: https://github.com/vacanza/holidays/blob/v0.105/holidays/countries/bangladesh.py | F13: HOLIDAY | G13: Da regole; non verificata singolarmente | H13: 0.105 | I13: 2026-09-23T20:51:39+00:00
A14: BD | B14: 46126 | C14: Bengali New Year's Day | D14: 1 | E14: https://github.com/vacanza/holidays/blob/v0.105/holidays/countries/bangladesh.py | F14: HOLIDAY | G14: Da regole; non verificata singolarmente | H14: 0.105 | I14: 2026-09-23T20:51:39+00:00
A15: BD | B15: 46143 | C15: May Day | D15: 1 | E15: https://github.com/vacanza/holidays/blob/v0.105/holidays/countries/bangladesh.py | F15: HOLIDAY | G15: Da regole; non verificata singolarmente | H15: 0.105 | I15: 2026-09-23T20:51:39+00:00
A16: BD | B16: 46170 | C16: Eid al-Adha | D16: 1 | E16: https://github.com/vacanza/holidays/blob/v0.105/holidays/countries/bangladesh.py | F16: HOLIDAY | G16: Da regole; non verificata singolarmente | H16: 0.105 | I16: 2026-09-23T20:51:39+00:00
A17: BD | B17: 46171 | C17: Eid al-Adha | D17: 1 | E17: https://github.com/vacanza/holidays/blob/v0.105/holidays/countries/bangladesh.py | F17: HOLIDAY | G17: Da regole; non verificata singolarmente | H17: 0.105 | I17: 2026-09-23T20:51:39+00:00
... A547: US | B547: 47112 | C547: Christmas Day | D547: 1 | E547: https://github.com/vacanza/holidays/blob/v0.105/holidays/countries/united_states.py | F547: HOLIDAY | G547: Da regole; non verificata singolarmente | H547: 0.105 | I547: 2026-09-23T20:51:39+00:00

Sheet Info
A1: Informazioni del Thurno e fasi Moon phases
A2: Information does not close availability. To close a day, add an active date in Calendars or in the CSV.
B3: {=IFERROR("Moon at view start: "&VLOOKUP(IF(ABS(Calcoli!B6-INDEX(MoonPhases[Utc],MATCH(Calcoli!B6,MoonPhases[Utc],1)))<1/1440,INDEX(MoonPhases[Phase],MATCH(Calcoli!B6,MoonPhases[Utc],1)),INDEX(MoonPhases[Between],MATCH(Calcoli!B6,MoonPhases[Utc],1))),Calcoli!$J$95:$K$102,2,FALSE)&" "&IF(ABS(Calcoli!B6-INDEX(MoonPhases[Utc],MATCH(Calcoli!B6,MoonPhases[Utc],1)))<1/1440,INDEX(MoonPhases[Phase],MATCH(Calcoli!B6,MoonPhases[Utc],1)),INDEX(MoonPhases[Between],MATCH(Calcoli!B6,MoonPhases[Utc],1)))&" | next: "&VLOOKUP(INDEX(MoonPhases[Phase],MATCH(Calcoli!B6,MoonPhases[Utc],1)+1),Calcoli!$J$95:$K$102,2,FALSE)&" "&INDEX(MoonPhases[Phase],MATCH(Calcoli!B6,MoonPhases[Utc],1)+1)&" "&RIGHT("0"&DAY(INDEX(MoonPhases[Utc],MATCH(Calcoli!B6,MoonPhases[Utc],1)+1)),2)&"/"&RIGHT("0"&MONTH(INDEX(MoonPhases[Utc],MATCH(Calcoli!B6,MoonPhases[Utc],1)+1)),2)&" "&RIGHT("0"&HOUR(INDEX(MoonPhases[Utc],MATCH(Calcoli!B6,MoonPhases[Utc],1)+1)),2)&":"&RIGHT("0"&MINUTE(INDEX(MoonPhases[Utc],MATCH(Calcoli!B6,MoonPhases[Utc],1)+1)),2)&" UTC","Moon: invalid date or outside coverage")} -> Moon at view start: 🌔 Waxing gibbous | next: 🌕 Full moon 26/09 16:49 UTC
B4: =IF(COUNTIF(Saints[Key],MONTH(Parametri!C5)*100+DAY(Parametri!C5))=0,"Observances: no data in the selection (not a complete calendar)","Observances (info only): "&LEFT(INDEX(Saints[Name],MATCH(MONTH(Parametri!C5)*100+DAY(Parametri!C5),Saints[Key],0)),110)&IF(LEN(INDEX(Saints[Name],MATCH(MONTH(Parametri!C5)*100+DAY(Parametri!C5),Saints[Key],0)))>110,"... see Info","")) -> Observances (info only): Blessed Virgin Mary of Mercy
A6: METEO ATTUALE - ultima lettura, non previsione per la data del Planner
A7: Code | B7: ObservedUtc | C7: FetchedUtc | D7: TemperatureC | E7: FeelsLikeC | F7: Description | G7: WindMs | H7: Status | I7: Source
A8: hanoi | B8: 46288.872 | C8: 46288.872 | D8: 26 | E8: 26 | F8: few clouds | G8: 0.53 | H8: fetched | I8: OpenWeather
A9: mumbai | B9: 46288.873 | C9: 46288.872 | D9: 29.01 | E9: 35.67 | F9: light rain | G9: 2.57 | H9: fetched | I9: OpenWeather
A10: minsk | B10: 46288.873 | C10: 46288.872 | D10: 8.75 | E10: 6.84 | F10: scattered clouds | G10: 3.29 | H10: fetched | I10: OpenWeather
A11: rome | B11: 46288.873 | C11: 46288.872 | D11: 20.8 | E11: 20.35 | F11: clear sky | G11: 0.51 | H11: fetched | I11: OpenWeather
A12: london | B12: 46288.872 | C12: 46288.872 | D12: 15.99 | E12: 15.37 | F12: scattered clouds | G12: 3.6 | H12: fetched | I12: OpenWeather
A13: new-york | B13: 46288.872 | C13: 46288.873 | D13: 20.04 | E13: 19.35 | F13: overcast | G13: 10.28 | H13: fetched | I13: OpenWeather
A14: los-angeles | B14: 46288.869 | C14: 46288.873 | D14: 28.61 | E14: 30.53 | F14: clear sky | G14: 5.66 | H14: fetched | I14: OpenWeather
A16: OpenWeather. ObservedUtc = observation; FetchedUtc = download. Dates and times are in UTC. Also read Status.
A17: Refresh tutto: chiave vuota in Parametri B32 = Weather.csv; chiave compilata = API OpenWeather per le città selezionate.
A18: The key is optional and stored as plain text. Do not share a workbook containing the key or the .key file.
A19: Fast Combine is enabled for this prototype. Excel's global privacy settings were not changed.
A26: SAINTS: informational selection of fixed observances, not a complete liturgical calendar. | G26: USNO PRIMARY PHASES 2025–2029. Instants in universal time; no effect on available hours.
A27: Key | B27: Month | C27: Day | D27: Name | E27: Source | G27: Utc | H27: Phase | I27: Between | J27: Source
A28: 102 | B28: 1 | C28: 2 | D28: Saints Basilio Magno and Gregorio Nazianzeno, bishops and dottori | E28: https://github.com/Liturgical-Calendar/LiturgicalCalendarAPI/blob/1bb2b7c503a701a9713b2f881795afe46044af3b/jsondata/sourcedata/rite/roman/missals/propriumdesanctis_1970/i18n/it.json; https://github.com/Liturgical-Calendar/LiturgicalCalendarAPI/blob/1bb2b7c503a701a9713b2f881795afe46044af3b/jsondata/sourcedata/rite/roman/missals/propriumdesanctis_1970/propriumdesanctis_1970.json | G28: 45663.997 | H28: First quarter | I28: Waxing gibbous | J28: https://aa.usno.navy.mil/api/moon/phases/year?year=2025
A29: 107 | B29: 1 | C29: 7 | D29: Saint Raimondo di Peñafort, priest | E29: https://github.com/Liturgical-Calendar/LiturgicalCalendarAPI/blob/1bb2b7c503a701a9713b2f881795afe46044af3b/jsondata/sourcedata/rite/roman/missals/propriumdesanctis_1970/i18n/it.json; https://github.com/Liturgical-Calendar/LiturgicalCalendarAPI/blob/1bb2b7c503a701a9713b2f881795afe46044af3b/jsondata/sourcedata/rite/roman/missals/propriumdesanctis_1970/propriumdesanctis_1970.json | G29: 45670.935 | H29: Full moon | I29: Waning gibbous | J29: https://aa.usno.navy.mil/api/moon/phases/year?year=2025
A30: 113 | B30: 1 | C30: 13 | D30: Saint Ilario di Poitiers, bishop and Doctor | E30: https://github.com/Liturgical-Calendar/LiturgicalCalendarAPI/blob/1bb2b7c503a701a9713b2f881795afe46044af3b/jsondata/sourcedata/rite/roman/missals/propriumdesanctis_1970/i18n/it.json; https://github.com/Liturgical-Calendar/LiturgicalCalendarAPI/blob/1bb2b7c503a701a9713b2f881795afe46044af3b/jsondata/sourcedata/rite/roman/missals/propriumdesanctis_1970/propriumdesanctis_1970.json | G30: 45678.855 | H30: Last quarter | I30: Waning crescent | J30: https://aa.usno.navy.mil/api/moon/phases/year?year=2025
A31: 117 | B31: 1 | C31: 17 | D31: Saint Antonio di Egitto, abbot | E31: https://github.com/Liturgical-Calendar/LiturgicalCalendarAPI/blob/1bb2b7c503a701a9713b2f881795afe46044af3b/jsondata/sourcedata/rite/roman/missals/propriumdesanctis_1970/i18n/it.json; https://github.com/Liturgical-Calendar/LiturgicalCalendarAPI/blob/1bb2b7c503a701a9713b2f881795afe46044af3b/jsondata/sourcedata/rite/roman/missals/propriumdesanctis_1970/propriumdesanctis_1970.json | G31: 45686.525 | H31: New moon | I31: Waxing crescent | J31: https://aa.usno.navy.mil/api/moon/phases/year?year=2025
